<?xml version="1.0" ?>
<!-- =================================================================================== -->
<!-- |    This document was autogenerated by xacro from swerveBOT.urdf.xacro           | -->
<!-- |    EDITING THIS FILE BY HAND IS NOT RECOMMENDED                                 | -->
<!-- =================================================================================== -->
<robot name="wheelbot">
  <material name="Aluminium">
    <color rgba="0.700 0.700 0.700 1.000"/>
  </material>
  <material name="PETG_orange">
    <color rgba="0.9 0.165 0.000 1.000"/>
  </material>
  <material name="Rubber">
    <color rgba="0 0 0 1.000"/>
  </material>
  <material name="invisible">
    <color rgba="0.0 0.0 0.0 0.0"/>
  </material>
  <link name="base_link"/>
  <link name="chassis_link">
    <collision>
      <origin rpy="0 0 0" xyz="0 0 0"/>
      <geometry>
        <box size="0.51 0.51 0.04"/>
      </geometry>
    </collision>
    <visual>
      <origin rpy="0 0 0" xyz="0 0 0"/>
      <geometry>
        <box size="0.51 0.51 0.04"/>
      </geometry>
      <material name="Aluminium"/>
    </visual>
    <inertial>
      <origin rpy="0 0 0" xyz="0 0 0"/>
      <mass value="5"/>
      <inertia ixx="0.000270" ixy="0.0" ixz="0.0" iyy="0.000270" iyz="0.0" izz="0.000426"/>
    </inertial>
  </link>
  <joint name="chassis_joint" type="fixed">
    <parent link="base_link"/>
    <child link="chassis_link"/>
    <origin rpy="0 0 0" xyz="0 0 0.217"/>
    <axis xyz="0 0 1"/>
    <dynamics damping="0.2"/>
  </joint>
  <link name="FL_steering_link">
    <visual>
      <origin rpy="0 0 0" xyz="0 0 0"/>
      <geometry>
        <cylinder length="0.032" radius="0.064"/>
      </geometry>
      <material name="Rubber"/>
    </visual>
  </link>
  <joint name="FL_steering_joint" type="revolute">
    <origin rpy="0 0 0" xyz="0.23500000000000001 0.215 -0.036000000000000004"/>
    <parent link="chassis_link"/>
    <child link="FL_steering_link"/>
    <axis xyz="0 0 1"/>
    <limit effort="100.0" lower="-1" upper="1" velocity="0.0"/>
    <dynamics damping="0.2"/>
  </joint>
  <link name="FL_chassis_2_link">
    <collision>
      <origin rpy="0 0 0" xyz="0 0 0"/>
      <geometry>
        <box size="0.09 0.16 0.09"/>
      </geometry>
    </collision>
    <visual>
      <origin rpy="0 0 0" xyz="0 0 0"/>
      <geometry>
        <box size="0.09 0.16 0.09"/>
      </geometry>
      <material name="Aluminium"/>
    </visual>
    <inertial>
      <origin rpy="0 0 0" xyz="0 0 0"/>
      <mass value="5"/>
      <inertia ixx="0.000270" ixy="0.0" ixz="0.0" iyy="0.000270" iyz="0.0" izz="0.000426"/>
    </inertial>
  </link>
  <joint name="FL_chassis_2_joint" type="fixed">
    <origin rpy="0 0 0" xyz="0 0 -0.0985"/>
    <parent link="FL_steering_link"/>
    <child link="FL_chassis_2_link"/>
  </joint>
  <link name="FL_wheel_drive_left">
    <collision>
      <origin rpy="1.5707963267948966 0 0" xyz="0 0 0"/>
      <geometry>
        <cylinder length="0.045" radius="0.0825"/>
      </geometry>
    </collision>
    <visual>
      <origin rpy="1.5707963267948966 0 1.5707963267948966" xyz="0 0 0"/>
      <geometry>
        <cylinder length="0.045" radius="0.0825"/>
      </geometry>
      <material name="PETG_orange"/>
    </visual>
    <inertial>
      <origin rpy="1.5707963267948966 0 1.5707963267948966" xyz="0 0 0"/>
      <mass value="0.3"/>
      <inertia ixx="0.0008167500000000001" ixy="0" ixz="0" iyy="0.0008167500000000001" iyz="0" izz="0.0008167500000000001"/>
    </inertial>
  </link>
  <joint name="FL_drive_left_joint" type="continuous">
    <origin rpy="0 0 1.5707963267948966" xyz="0 0.115 0"/>
    <parent link="FL_chassis_2_link"/>
    <child link="FL_wheel_drive_left"/>
    <axis xyz="1 0 0"/>
    <limit effort="100.0" velocity="100.0"/>
    <dynamics damping="0.2"/>
  </joint>
  <link name="FL_wheel_drive_right">
    <collision>
      <origin rpy="1.5707963267948966 0 0" xyz="0 0 0"/>
      <geometry>
        <cylinder length="0.045" radius="0.0825"/>
      </geometry>
    </collision>
    <visual>
      <origin rpy="1.5707963267948966 0 1.5707963267948966" xyz="0 0 0"/>
      <geometry>
        <cylinder length="0.045" radius="0.0825"/>
      </geometry>
      <material name="PETG_orange"/>
    </visual>
    <inertial>
      <origin rpy="1.5707963267948966 0 1.5707963267948966" xyz="0 0 0"/>
      <mass value="0.3"/>
      <inertia ixx="0.0008167500000000001" ixy="0" ixz="0" iyy="0.0008167500000000001" iyz="0" izz="0.0008167500000000001"/>
    </inertial>
  </link>
  <joint name="FL_drive_right_joint" type="continuous">
    <origin rpy="0 0 1.5707963267948966" xyz="0 -0.115 0"/>
    <parent link="FL_chassis_2_link"/>
    <child link="FL_wheel_drive_right"/>
    <axis xyz="1 0 0"/>
    <limit effort="100.0" velocity="100.0"/>
    <dynamics damping="0.2"/>
  </joint>
  <link name="FR_steering_link">
    <visual>
      <origin rpy="0 0 0" xyz="0 0 0"/>
      <geometry>
        <cylinder length="0.032" radius="0.064"/>
      </geometry>
      <material name="Rubber"/>
    </visual>
  </link>
  <joint name="FR_steering_joint" type="revolute">
    <origin rpy="0 0 0" xyz="0.23500000000000001 -0.215 -0.036000000000000004"/>
    <parent link="chassis_link"/>
    <child link="FR_steering_link"/>
    <axis xyz="0 0 1"/>
    <limit effort="100.0" lower="-1" upper="1" velocity="0.0"/>
    <dynamics damping="0.2"/>
  </joint>
  <link name="FR_chassis_2_link">
    <collision>
      <origin rpy="0 0 0" xyz="0 0 0"/>
      <geometry>
        <box size="0.09 0.16 0.09"/>
      </geometry>
    </collision>
    <visual>
      <origin rpy="0 0 0" xyz="0 0 0"/>
      <geometry>
        <box size="0.09 0.16 0.09"/>
      </geometry>
      <material name="Aluminium"/>
    </visual>
    <inertial>
      <origin rpy="0 0 0" xyz="0 0 0"/>
      <mass value="5"/>
      <inertia ixx="0.000270" ixy="0.0" ixz="0.0" iyy="0.000270" iyz="0.0" izz="0.000426"/>
    </inertial>
  </link>
  <joint name="FR_chassis_2_joint" type="fixed">
    <origin rpy="0 0 0" xyz="0 0 -0.0985"/>
    <parent link="FR_steering_link"/>
    <child link="FR_chassis_2_link"/>
  </joint>
  <link name="FR_wheel_drive_left">
    <collision>
      <origin rpy="1.5707963267948966 0 0" xyz="0 0 0"/>
      <geometry>
        <cylinder length="0.045" radius="0.0825"/>
      </geometry>
    </collision>
    <visual>
      <origin rpy="1.5707963267948966 0 1.5707963267948966" xyz="0 0 0"/>
      <geometry>
        <cylinder length="0.045" radius="0.0825"/>
      </geometry>
      <material name="PETG_orange"/>
    </visual>
    <inertial>
      <origin rpy="1.5707963267948966 0 1.5707963267948966" xyz="0 0 0"/>
      <mass value="0.3"/>
      <inertia ixx="0.0008167500000000001" ixy="0" ixz="0" iyy="0.0008167500000000001" iyz="0" izz="0.0008167500000000001"/>
    </inertial>
  </link>
  <joint name="FR_drive_left_joint" type="continuous">
    <origin rpy="0 0 1.5707963267948966" xyz="0 0.115 0"/>
    <parent link="FR_chassis_2_link"/>
    <child link="FR_wheel_drive_left"/>
    <axis xyz="1 0 0"/>
    <limit effort="100.0" velocity="100.0"/>
    <dynamics damping="0.2"/>
  </joint>
  <link name="FR_wheel_drive_right">
    <collision>
      <origin rpy="1.5707963267948966 0 0" xyz="0 0 0"/>
      <geometry>
        <cylinder length="0.045" radius="0.0825"/>
      </geometry>
    </collision>
    <visual>
      <origin rpy="1.5707963267948966 0 1.5707963267948966" xyz="0 0 0"/>
      <geometry>
        <cylinder length="0.045" radius="0.0825"/>
      </geometry>
      <material name="PETG_orange"/>
    </visual>
    <inertial>
      <origin rpy="1.5707963267948966 0 1.5707963267948966" xyz="0 0 0"/>
      <mass value="0.3"/>
      <inertia ixx="0.0008167500000000001" ixy="0" ixz="0" iyy="0.0008167500000000001" iyz="0" izz="0.0008167500000000001"/>
    </inertial>
  </link>
  <joint name="FR_drive_right_joint" type="continuous">
    <origin rpy="0 0 1.5707963267948966" xyz="0 -0.115 0"/>
    <parent link="FR_chassis_2_link"/>
    <child link="FR_wheel_drive_right"/>
    <axis xyz="1 0 0"/>
    <limit effort="100.0" velocity="100.0"/>
    <dynamics damping="0.2"/>
  </joint>
  <link name="RL_steering_link">
    <visual>
      <origin rpy="0 0 0" xyz="0 0 0"/>
      <geometry>
        <cylinder length="0.032" radius="0.064"/>
      </geometry>
      <material name="Rubber"/>
    </visual>
  </link>
  <joint name="RL_steering_joint" type="revolute">
    <origin rpy="0 0 0" xyz="-0.23500000000000001 0.215 -0.036000000000000004"/>
    <parent link="chassis_link"/>
    <child link="RL_steering_link"/>
    <axis xyz="0 0 1"/>
    <limit effort="100.0" lower="-1" upper="1" velocity="0.0"/>
    <dynamics damping="0.2"/>
  </joint>
  <link name="RL_chassis_2_link">
    <collision>
      <origin rpy="0 0 0" xyz="0 0 0"/>
      <geometry>
        <box size="0.09 0.16 0.09"/>
      </geometry>
    </collision>
    <visual>
      <origin rpy="0 0 0" xyz="0 0 0"/>
      <geometry>
        <box size="0.09 0.16 0.09"/>
      </geometry>
      <material name="Aluminium"/>
    </visual>
    <inertial>
      <origin rpy="0 0 0" xyz="0 0 0"/>
      <mass value="5"/>
      <inertia ixx="0.000270" ixy="0.0" ixz="0.0" iyy="0.000270" iyz="0.0" izz="0.000426"/>
    </inertial>
  </link>
  <joint name="RL_chassis_2_joint" type="fixed">
    <origin rpy="0 0 0" xyz="0 0 -0.0985"/>
    <parent link="RL_steering_link"/>
    <child link="RL_chassis_2_link"/>
  </joint>
  <link name="RL_wheel_drive_left">
    <collision>
      <origin rpy="1.5707963267948966 0 0" xyz="0 0 0"/>
      <geometry>
        <cylinder length="0.045" radius="0.0825"/>
      </geometry>
    </collision>
    <visual>
      <origin rpy="1.5707963267948966 0 1.5707963267948966" xyz="0 0 0"/>
      <geometry>
        <cylinder length="0.045" radius="0.0825"/>
      </geometry>
      <material name="PETG_orange"/>
    </visual>
    <inertial>
      <origin rpy="1.5707963267948966 0 1.5707963267948966" xyz="0 0 0"/>
      <mass value="0.3"/>
      <inertia ixx="0.0008167500000000001" ixy="0" ixz="0" iyy="0.0008167500000000001" iyz="0" izz="0.0008167500000000001"/>
    </inertial>
  </link>
  <joint name="RL_drive_left_joint" type="continuous">
    <origin rpy="0 0 1.5707963267948966" xyz="0 0.115 0"/>
    <parent link="RL_chassis_2_link"/>
    <child link="RL_wheel_drive_left"/>
    <axis xyz="1 0 0"/>
    <limit effort="100.0" velocity="100.0"/>
    <dynamics damping="0.2"/>
  </joint>
  <link name="RL_wheel_drive_right">
    <collision>
      <origin rpy="1.5707963267948966 0 0" xyz="0 0 0"/>
      <geometry>
        <cylinder length="0.045" radius="0.0825"/>
      </geometry>
    </collision>
    <visual>
      <origin rpy="1.5707963267948966 0 1.5707963267948966" xyz="0 0 0"/>
      <geometry>
        <cylinder length="0.045" radius="0.0825"/>
      </geometry>
      <material name="PETG_orange"/>
    </visual>
    <inertial>
      <origin rpy="1.5707963267948966 0 1.5707963267948966" xyz="0 0 0"/>
      <mass value="0.3"/>
      <inertia ixx="0.0008167500000000001" ixy="0" ixz="0" iyy="0.0008167500000000001" iyz="0" izz="0.0008167500000000001"/>
    </inertial>
  </link>
  <joint name="RL_drive_right_joint" type="continuous">
    <origin rpy="0 0 1.5707963267948966" xyz="0 -0.115 0"/>
    <parent link="RL_chassis_2_link"/>
    <child link="RL_wheel_drive_right"/>
    <axis xyz="1 0 0"/>
    <limit effort="100.0" velocity="100.0"/>
    <dynamics damping="0.2"/>
  </joint>
  <link name="RR_steering_link">
    <visual>
      <origin rpy="0 0 0" xyz="0 0 0"/>
      <geometry>
        <cylinder length="0.032" radius="0.064"/>
      </geometry>
      <material name="Rubber"/>
    </visual>
  </link>
  <joint name="RR_steering_joint" type="revolute">
    <origin rpy="0 0 0" xyz="-0.23500000000000001 -0.215 -0.036000000000000004"/>
    <parent link="chassis_link"/>
    <child link="RR_steering_link"/>
    <axis xyz="0 0 1"/>
    <limit effort="100.0" lower="-1" upper="1" velocity="0.0"/>
    <dynamics damping="0.2"/>
  </joint>
  <link name="RR_chassis_2_link">
    <collision>
      <origin rpy="0 0 0" xyz="0 0 0"/>
      <geometry>
        <box size="0.09 0.16 0.09"/>
      </geometry>
    </collision>
    <visual>
      <origin rpy="0 0 0" xyz="0 0 0"/>
      <geometry>
        <box size="0.09 0.16 0.09"/>
      </geometry>
      <material name="Aluminium"/>
    </visual>
    <inertial>
      <origin rpy="0 0 0" xyz="0 0 0"/>
      <mass value="5"/>
      <inertia ixx="0.000270" ixy="0.0" ixz="0.0" iyy="0.000270" iyz="0.0" izz="0.000426"/>
    </inertial>
  </link>
  <joint name="RR_chassis_2_joint" type="fixed">
    <origin rpy="0 0 0" xyz="0 0 -0.0985"/>
    <parent link="RR_steering_link"/>
    <child link="RR_chassis_2_link"/>
  </joint>
  <link name="RR_wheel_drive_left">
    <collision>
      <origin rpy="1.5707963267948966 0 0" xyz="0 0 0"/>
      <geometry>
        <cylinder length="0.045" radius="0.0825"/>
      </geometry>
    </collision>
    <visual>
      <origin rpy="1.5707963267948966 0 1.5707963267948966" xyz="0 0 0"/>
      <geometry>
        <cylinder length="0.045" radius="0.0825"/>
      </geometry>
      <material name="PETG_orange"/>
    </visual>
    <inertial>
      <origin rpy="1.5707963267948966 0 1.5707963267948966" xyz="0 0 0"/>
      <mass value="0.3"/>
      <inertia ixx="0.0008167500000000001" ixy="0" ixz="0" iyy="0.0008167500000000001" iyz="0" izz="0.0008167500000000001"/>
    </inertial>
  </link>
  <joint name="RR_drive_left_joint" type="continuous">
    <origin rpy="0 0 1.5707963267948966" xyz="0 0.115 0"/>
    <parent link="RR_chassis_2_link"/>
    <child link="RR_wheel_drive_left"/>
    <axis xyz="1 0 0"/>
    <limit effort="100.0" velocity="100.0"/>
    <dynamics damping="0.2"/>
  </joint>
  <link name="RR_wheel_drive_right">
    <collision>
      <origin rpy="1.5707963267948966 0 0" xyz="0 0 0"/>
      <geometry>
        <cylinder length="0.045" radius="0.0825"/>
      </geometry>
    </collision>
    <visual>
      <origin rpy="1.5707963267948966 0 1.5707963267948966" xyz="0 0 0"/>
      <geometry>
        <cylinder length="0.045" radius="0.0825"/>
      </geometry>
      <material name="PETG_orange"/>
    </visual>
    <inertial>
      <origin rpy="1.5707963267948966 0 1.5707963267948966" xyz="0 0 0"/>
      <mass value="0.3"/>
      <inertia ixx="0.0008167500000000001" ixy="0" ixz="0" iyy="0.0008167500000000001" iyz="0" izz="0.0008167500000000001"/>
    </inertial>
  </link>
  <joint name="RR_drive_right_joint" type="continuous">
    <origin rpy="0 0 1.5707963267948966" xyz="0 -0.115 0"/>
    <parent link="RR_chassis_2_link"/>
    <child link="RR_wheel_drive_right"/>
    <axis xyz="1 0 0"/>
    <limit effort="100.0" velocity="100.0"/>
    <dynamics damping="0.2"/>
  </joint>

</robot>
