<?xml version="1.0"?>
<robot xmlns:xacro="http://ros.org/wiki/xacro">
  
    
  <xacro:macro name="virtual_swerve_module" params="
        prefix parent
        pos_x pos_y pos_z"
    >
  
    <!--********************************************* STEERING *****************************************************************   -->  
  
    <!-- virtual front right steering -->
    <link name="${prefix}virtual_front_right_steering_link">
    </link>

    <joint name="${prefix}virtual_front_right_steering_joint" type="revolute">
      <parent link="${parent}"/>
      <child link="${prefix}virtual_front_right_steering_link"/>
      <origin xyz="${pos_x} -${pos_y} ${pos_z}" rpy="0 0 0"/>
      <axis xyz="0 0 1"/>
      <limit lower="-${PI}" upper="${PI}" effort="100.0" velocity="10.0"/>
    </joint>

    <!-- virtual rear left steering -->
    <link name="${prefix}virtual_rear_left_steering_link">
    </link>

    <joint name="${prefix}virtual_rear_left_steering_joint" type="revolute">
      <parent link="${parent}"/>
      <child link="${prefix}virtual_rear_left_steering_link"/>
      <origin xyz="-${pos_x} ${pos_y} ${pos_z}" rpy="0 0 0"/>
      <axis xyz="0 0 1"/>
      <limit lower="-${PI}" upper="${PI}" effort="100.0" velocity="10.0"/>
    </joint>


    <!-- virtual rear right steering -->
    <link name="${prefix}virtual_rear_right_steering_link">
    </link>

    <joint name="${prefix}virtual_rear_right_steering_joint" type="revolute">
      <parent link="${parent}"/>
      <child link="${prefix}virtual_rear_right_steering_link"/>
      <origin xyz="-${pos_x} -${pos_y} ${pos_z}" rpy="0 0 0"/>
      <axis xyz="0 0 1"/>
      <limit lower="-${PI}" upper="${PI}" effort="100.0" velocity="10.0"/>
    </joint>


    <!-- virtual front left steering -->
    <link name="${prefix}virtual_front_left_steering_link">
    </link>

    <joint name="${prefix}virtual_front_left_steering_joint" type="revolute">
      <parent link="${parent}"/>
      <child link="${prefix}virtual_front_left_steering_link"/>
      <origin xyz="${pos_x} ${pos_y} ${pos_z}" rpy="0 0 0"/>
      <axis xyz="0 0 1"/>
      <limit lower="-${PI}" upper="${PI}" effort="100.0" velocity="10.0"/>
    </joint>


    <!--********************************************* TRACTION *****************************************************************   -->
  
    <!-- virtual front right wheel -->
    <link name="${prefix}virtual_front_right_wheel_link">
    </link>

    <joint name="${prefix}virtual_front_right_wheel_joint" type="continuous">
      <parent link="${prefix}virtual_front_right_steering_link"/>
      <child link="${prefix}virtual_front_right_wheel_link"/>
      <origin xyz="0 0 0" rpy="0 0 0"/>
      <axis xyz="0 1 0"/>
    </joint>
  
    <!-- virtual rear left wheel RL -->
    <link name="${prefix}virtual_rear_left_wheel_link">
    </link>

    <joint name="${prefix}virtual_rear_left_wheel_joint" type="continuous">
      <parent link="${prefix}virtual_rear_left_steering_link"/>
      <child link="${prefix}virtual_rear_left_wheel_link"/>
      <origin xyz="0 0 0" rpy="0 0 0"/>
      <axis xyz="0 1 0"/>
    </joint>

    <!-- virtual rear right wheel RR -->
    <link name="${prefix}virtual_rear_right_wheel_link">
    </link>

    <joint name="${prefix}virtual_rear_right_wheel_joint" type="continuous">
      <parent link="${prefix}virtual_rear_right_steering_link"/>
      <child link="${prefix}virtual_rear_right_wheel_link"/>
      <origin xyz="0 0 0" rpy="0 0 0"/>
      <axis xyz="0 1 0"/>
    </joint>

    <!-- virtual front left wheel -->
    <link name="${prefix}virtual_front_left_wheel_link">
    </link>

    <joint name="${prefix}virtual_front_left_wheel_joint" type="continuous">
      <parent link="${prefix}virtual_front_left_steering_link"/>
      <child link="${prefix}virtual_front_left_wheel_link"/>
      <origin xyz="0 0 0" rpy="0 0 0"/>
      <axis xyz="0 1 0"/>
    </joint>

  </xacro:macro>

</robot>
