#usda 1.0
(
    customLayerData = {
        dictionary cameraSettings = {
            dictionary Front = {
                double3 position = (5, 0, 0)
                double radius = 5
            }
            dictionary Perspective = {
                double3 position = (1.4006287012139969, 1.4006287012139982, 1.4006287871246206)
                double3 target = (-3.97803838758648e-8, -3.978038209950796e-8, 7.956076930604183e-8)
            }
            dictionary Right = {
                double3 position = (0, -5, 0)
                double radius = 5
            }
            dictionary Top = {
                double3 position = (0, 0, 5)
                double radius = 5
            }
            string boundCamera = "/OmniverseKit_Persp"
        }
        dictionary omni_layer = {
            string authoring_layer = "./swerveBOT.usda"
            dictionary locked = {
            }
            dictionary muteness = {
            }
        }
        dictionary renderSettings = {
            float3 "rtx:debugView:pixelDebug:textColor" = (0, 1e18, 0)
            float3 "rtx:fog:fogColor" = (0.75, 0.75, 0.75)
            float3 "rtx:index:backgroundColor" = (0, 0, 0)
            float3 "rtx:index:regionOfInterestMax" = (0, 0, 0)
            float3 "rtx:index:regionOfInterestMin" = (0, 0, 0)
            float3 "rtx:post:backgroundZeroAlpha:backgroundDefaultColor" = (0, 0, 0)
            float3 "rtx:post:colorcorr:contrast" = (1, 1, 1)
            float3 "rtx:post:colorcorr:gain" = (1, 1, 1)
            float3 "rtx:post:colorcorr:gamma" = (1, 1, 1)
            float3 "rtx:post:colorcorr:offset" = (0, 0, 0)
            float3 "rtx:post:colorcorr:saturation" = (1, 1, 1)
            float3 "rtx:post:colorgrad:blackpoint" = (0, 0, 0)
            float3 "rtx:post:colorgrad:contrast" = (1, 1, 1)
            float3 "rtx:post:colorgrad:gain" = (1, 1, 1)
            float3 "rtx:post:colorgrad:gamma" = (1, 1, 1)
            float3 "rtx:post:colorgrad:lift" = (0, 0, 0)
            float3 "rtx:post:colorgrad:multiply" = (1, 1, 1)
            float3 "rtx:post:colorgrad:offset" = (0, 0, 0)
            float3 "rtx:post:colorgrad:whitepoint" = (1, 1, 1)
            float3 "rtx:post:lensDistortion:lensFocalLengthArray" = (10, 30, 50)
            float3 "rtx:post:lensFlares:anisoFlareFalloffX" = (450, 475, 500)
            float3 "rtx:post:lensFlares:anisoFlareFalloffY" = (10, 10, 10)
            float3 "rtx:post:lensFlares:cutoffPoint" = (2, 2, 2)
            float3 "rtx:post:lensFlares:haloFlareFalloff" = (10, 10, 10)
            float3 "rtx:post:lensFlares:haloFlareRadius" = (75, 75, 75)
            float3 "rtx:post:lensFlares:isotropicFlareFalloff" = (50, 50, 50)
            float3 "rtx:post:lensFlares:spectralBlurWavelengthRange" = (380, 550, 770)
            float3 "rtx:post:tonemap:whitepoint" = (1, 1, 1)
            float3 "rtx:raytracing:indexdirect:svoBrickSize" = (32, 32, 32)
            float3 "rtx:raytracing:inscattering:singleScatteringAlbedo" = (0.9, 0.9, 0.9)
            float3 "rtx:raytracing:inscattering:transmittanceColor" = (0.5, 0.5, 0.5)
            float3 "rtx:sceneDb:ambientLightColor" = (0.1, 0.1, 0.1)
            float2 "rtx:viewTile:resolution" = (0, 0)
        }
    }
    defaultPrim = "wheelbot"
    doc = """Generated from Composed Stage of root layer /home/george/ROS2/ros2_wheelbot/src/description/urdf/robots/swerveBOT/swerveBOT.usd


Generated from Composed Stage of root layer /home/george/ROS2/ros2_wheelbot/src/description/urdf/robots/swerveBOT/swerveBOT.usd
"""
    metersPerUnit = 1
    upAxis = "Z"
)

def Xform "wheelbot"
{
    quatd xformOp:orient = (1, 0, 0, 0)
    double3 xformOp:scale = (1, 1, 1)
    double3 xformOp:translate = (0, 0, 0)
    uniform token[] xformOpOrder = ["xformOp:translate", "xformOp:orient", "xformOp:scale"]

    def Scope "Looks"
    {
        def Material "material_Aluminium"
        {
            token outputs:mdl:displacement.connect = </wheelbot/Looks/material_Aluminium/Shader.outputs:out>
            token outputs:mdl:surface.connect = </wheelbot/Looks/material_Aluminium/Shader.outputs:out>
            token outputs:mdl:volume.connect = </wheelbot/Looks/material_Aluminium/Shader.outputs:out>

            def Shader "Shader"
            {
                uniform token info:implementationSource = "sourceAsset"
                uniform asset info:mdl:sourceAsset = @OmniPBR.mdl@
                uniform token info:mdl:sourceAsset:subIdentifier = "OmniPBR"
                color3f inputs:diffuse_color_constant = (0.7, 0.7, 0.7)
                token outputs:out
            }
        }

        def Material "material_PETG_orange"
        {
            token outputs:mdl:displacement.connect = </wheelbot/Looks/material_PETG_orange/Shader.outputs:out>
            token outputs:mdl:surface.connect = </wheelbot/Looks/material_PETG_orange/Shader.outputs:out>
            token outputs:mdl:volume.connect = </wheelbot/Looks/material_PETG_orange/Shader.outputs:out>

            def Shader "Shader"
            {
                uniform token info:implementationSource = "sourceAsset"
                uniform asset info:mdl:sourceAsset = @OmniPBR.mdl@
                uniform token info:mdl:sourceAsset:subIdentifier = "OmniPBR"
                color3f inputs:diffuse_color_constant = (0.9, 0.165, 0)
                token outputs:out
            }
        }

        def Material "material_Rubber"
        {
            token outputs:mdl:displacement.connect = </wheelbot/Looks/material_Rubber/Shader.outputs:out>
            token outputs:mdl:surface.connect = </wheelbot/Looks/material_Rubber/Shader.outputs:out>
            token outputs:mdl:volume.connect = </wheelbot/Looks/material_Rubber/Shader.outputs:out>

            def Shader "Shader"
            {
                uniform token info:implementationSource = "sourceAsset"
                uniform asset info:mdl:sourceAsset = @OmniPBR.mdl@
                uniform token info:mdl:sourceAsset:subIdentifier = "OmniPBR"
                color3f inputs:diffuse_color_constant = (0, 0, 0)
                token outputs:out
            }
        }

        def Material "material_invisible"
        {
            token outputs:mdl:displacement.connect = </wheelbot/Looks/material_invisible/Shader.outputs:out>
            token outputs:mdl:surface.connect = </wheelbot/Looks/material_invisible/Shader.outputs:out>
            token outputs:mdl:volume.connect = </wheelbot/Looks/material_invisible/Shader.outputs:out>

            def Shader "Shader"
            {
                uniform token info:implementationSource = "sourceAsset"
                uniform asset info:mdl:sourceAsset = @OmniPBR.mdl@
                uniform token info:mdl:sourceAsset:subIdentifier = "OmniPBR"
                color3f inputs:diffuse_color_constant = (0, 0, 0)
                token outputs:out
            }
        }
    }

    def Xform "base_link" (
        apiSchemas = ["PhysicsRigidBodyAPI", "PhysicsMassAPI", "PhysicsArticulationRootAPI", "PhysxArticulationAPI"]
    )
    {
        float3 physics:diagonalInertia = (0.00001, 0.00001, 0.00001)
        float physics:mass = 0.000001
        bool physxArticulation:enabledSelfCollisions = 0
        int physxArticulation:solverPositionIterationCount = 32
        int physxArticulation:solverVelocityIterationCount = 1
        quatd xformOp:orient = (1, 0, 0, 0)
        double3 xformOp:scale = (1, 1, 1)
        double3 xformOp:translate = (0, 0, 0)
        uniform token[] xformOpOrder = ["xformOp:translate", "xformOp:orient", "xformOp:scale"]
    }

    def Xform "chassis_link" (
        apiSchemas = ["PhysicsRigidBodyAPI", "PhysicsMassAPI"]
    )
    {
        point3f physics:centerOfMass = (0, 0, 0)
        float physics:mass = 5
        quatd xformOp:orient = (1, 0, 0, 0)
        double3 xformOp:scale = (1, 1, 1)
        double3 xformOp:translate = (0, 0, 0.21699999272823334)
        uniform token[] xformOpOrder = ["xformOp:translate", "xformOp:orient", "xformOp:scale"]

        def Cube "visuals"
        {
            float3[] extent = [(-0.255, -0.255, -0.02), (0.255, 0.255, 0.02)]
            rel material:binding = </wheelbot/Looks/material_Aluminium>
            double size = 1
            quatd xformOp:orient = (1, 0, 0, 0)
            double3 xformOp:scale = (0.5099999904632568, 0.5099999904632568, 0.03999999910593033)
            double3 xformOp:translate = (0, 0, 0)
            uniform token[] xformOpOrder = ["xformOp:translate", "xformOp:orient", "xformOp:scale"]
        }

        def Cube "collisions" (
            apiSchemas = ["PhysicsCollisionAPI"]
        )
        {
            float3[] extent = [(-0.255, -0.255, -0.02), (0.255, 0.255, 0.02)]
            uniform token purpose = "guide"
            double size = 1
            quatd xformOp:orient = (1, 0, 0, 0)
            double3 xformOp:scale = (0.5099999904632568, 0.5099999904632568, 0.03999999910593033)
            double3 xformOp:translate = (0, 0, 0)
            uniform token[] xformOpOrder = ["xformOp:translate", "xformOp:orient", "xformOp:scale"]
        }

        def PhysicsFixedJoint "chassis_joint"
        {
            rel physics:body0 = </wheelbot/base_link>
            rel physics:body1 = </wheelbot/chassis_link>
            float physics:breakForce = 3.4028235e38
            float physics:breakTorque = 3.4028235e38
            point3f physics:localPos0 = (0, 0, 0.217)
            point3f physics:localPos1 = (0, 0, 0)
            quatf physics:localRot0 = (1, 0, 0, 0)
            quatf physics:localRot1 = (1, 0, 0, 0)
        }
    }

    def Xform "FL_steering_link" (
        apiSchemas = ["PhysicsRigidBodyAPI", "PhysicsMassAPI"]
    )
    {
        float3 physics:diagonalInertia = (0.00001, 0.00001, 0.00001)
        float physics:mass = 0.000001
        quatd xformOp:orient = (1, 0, 0, 0)
        double3 xformOp:scale = (1, 1, 1)
        double3 xformOp:translate = (0.23499999940395355, 0.2150000035762787, 0.1809999942779541)
        uniform token[] xformOpOrder = ["xformOp:translate", "xformOp:orient", "xformOp:scale"]

        def Cylinder "visuals"
        {
            uniform token axis = "Z"
            float3[] extent = [(-0.064, -0.064, -0.016), (0.064, 0.064, 0.016)]
            double height = 0.03200000151991844
            rel material:binding = </wheelbot/Looks/material_Rubber>
            double radius = 0.06400000303983688
            quatd xformOp:orient = (1, 0, 0, 0)
            double3 xformOp:scale = (1, 1, 1)
            double3 xformOp:translate = (0, 0, 0)
            uniform token[] xformOpOrder = ["xformOp:translate", "xformOp:orient", "xformOp:scale"]
        }

        def PhysicsRevoluteJoint "FL_steering_joint" (
            apiSchemas = ["PhysxJointAPI", "PhysicsJointStateAPI:angular"]
        )
        {
            float drive:angular:physics:damping = 0.2
            float drive:angular:physics:maxForce = 100
            float drive:angular:physics:stiffness = 0
            uniform token drive:angular:physics:type = "force"
            uniform token physics:axis = "Z"
            rel physics:body0 = </wheelbot/chassis_link>
            rel physics:body1 = </wheelbot/FL_steering_link>
            float physics:breakForce = 3.4028235e38
            float physics:breakTorque = 3.4028235e38
            point3f physics:localPos0 = (0.235, 0.215, -0.036)
            point3f physics:localPos1 = (0, 0, 0)
            quatf physics:localRot0 = (1, 0, 0, 0)
            quatf physics:localRot1 = (1, 0, 0, 0)
            float physics:lowerLimit = -57.295776
            float physics:upperLimit = 57.295776
            float physxJoint:maxJointVelocity = 3.4028235e38
        }
    }

    def Xform "FL_chassis_2_link" (
        apiSchemas = ["PhysicsRigidBodyAPI", "PhysicsMassAPI"]
    )
    {
        point3f physics:centerOfMass = (0, 0, 0)
        float physics:mass = 5
        quatd xformOp:orient = (1, 0, 0, 0)
        double3 xformOp:scale = (1, 1, 1)
        double3 xformOp:translate = (0.23499999940395355, 0.2150000035762787, 0.08249999582767487)
        uniform token[] xformOpOrder = ["xformOp:translate", "xformOp:orient", "xformOp:scale"]

        def Cube "visuals"
        {
            float3[] extent = [(-0.045, -0.08, -0.045), (0.045, 0.08, 0.045)]
            rel material:binding = </wheelbot/Looks/material_Aluminium>
            double size = 1
            quatd xformOp:orient = (1, 0, 0, 0)
            double3 xformOp:scale = (0.09000000357627869, 0.1599999964237213, 0.09000000357627869)
            double3 xformOp:translate = (0, 0, 0)
            uniform token[] xformOpOrder = ["xformOp:translate", "xformOp:orient", "xformOp:scale"]
        }

        def Cube "collisions" (
            apiSchemas = ["PhysicsCollisionAPI"]
        )
        {
            float3[] extent = [(-0.045, -0.08, -0.045), (0.045, 0.08, 0.045)]
            uniform token purpose = "guide"
            double size = 1
            quatd xformOp:orient = (1, 0, 0, 0)
            double3 xformOp:scale = (0.09000000357627869, 0.1599999964237213, 0.09000000357627869)
            double3 xformOp:translate = (0, 0, 0)
            uniform token[] xformOpOrder = ["xformOp:translate", "xformOp:orient", "xformOp:scale"]
        }

        def PhysicsFixedJoint "FL_chassis_2_joint"
        {
            rel physics:body0 = </wheelbot/FL_steering_link>
            rel physics:body1 = </wheelbot/FL_chassis_2_link>
            float physics:breakForce = 3.4028235e38
            float physics:breakTorque = 3.4028235e38
            point3f physics:localPos0 = (0, 0, -0.0985)
            point3f physics:localPos1 = (0, 0, 0)
            quatf physics:localRot0 = (1, 0, 0, 0)
            quatf physics:localRot1 = (1, 0, 0, 0)
        }
    }

    def Xform "FL_wheel_drive_left" (
        apiSchemas = ["PhysicsRigidBodyAPI", "PhysicsMassAPI"]
    )
    {
        point3f physics:centerOfMass = (0, 0, 0)
        float physics:mass = 0.3
        quatd xformOp:orient = (0.7071067690849304, 0, 0, 0.7071067690849304)
        double3 xformOp:scale = (1, 1, 1)
        double3 xformOp:translate = (0.23499999940395355, 0.33000001311302185, 0.08249999582767487)
        uniform token[] xformOpOrder = ["xformOp:translate", "xformOp:orient", "xformOp:scale"]

        def Cylinder "visuals"
        {
            uniform token axis = "Z"
            float3[] extent = [(-0.0825, -0.0825, -0.0225), (0.0825, 0.0825, 0.0225)]
            double height = 0.04500000178813934
            rel material:binding = </wheelbot/Looks/material_PETG_orange>
            double radius = 0.08250000327825546
            quatd xformOp:orient = (0.4999999701976776, 0.4999999701976776, 0.4999999701976776, 0.4999999701976776)
            double3 xformOp:scale = (1, 1, 1)
            double3 xformOp:translate = (0, 0, 0)
            uniform token[] xformOpOrder = ["xformOp:translate", "xformOp:orient", "xformOp:scale"]
        }

        def Cylinder "collisions" (
            apiSchemas = ["PhysicsCollisionAPI"]
        )
        {
            uniform token axis = "Z"
            float3[] extent = [(-0.0825, -0.0825, -0.0225), (0.0825, 0.0825, 0.0225)]
            double height = 0.04500000178813934
            uniform token purpose = "guide"
            double radius = 0.08250000327825546
            quatd xformOp:orient = (0.7071067690849304, 0.7071067690849304, 0, 0)
            double3 xformOp:scale = (1, 1, 1)
            double3 xformOp:translate = (0, 0, 0)
            uniform token[] xformOpOrder = ["xformOp:translate", "xformOp:orient", "xformOp:scale"]
        }

        def PhysicsRevoluteJoint "FL_drive_left_joint" (
            apiSchemas = ["PhysxJointAPI", "PhysicsJointStateAPI:angular", "PhysicsDriveAPI:angular"]
        )
        {
            float drive:angular:physics:damping = 1000000
            float drive:angular:physics:maxForce = 100
            float drive:angular:physics:stiffness = 0
            float drive:angular:physics:targetVelocity = 0
            uniform token drive:angular:physics:type = "force"
            uniform token physics:axis = "X"
            rel physics:body0 = </wheelbot/FL_chassis_2_link>
            rel physics:body1 = </wheelbot/FL_wheel_drive_left>
            float physics:breakForce = 3.4028235e38
            float physics:breakTorque = 3.4028235e38
            point3f physics:localPos0 = (0, 0.115, 0)
            point3f physics:localPos1 = (0, 0, 0)
            quatf physics:localRot0 = (0.70710677, 0, 0, 0.70710677)
            quatf physics:localRot1 = (1, 0, 0, 0)
            float physxJoint:maxJointVelocity = 5729.578
        }
    }

    def Xform "FL_wheel_drive_right" (
        apiSchemas = ["PhysicsRigidBodyAPI", "PhysicsMassAPI"]
    )
    {
        point3f physics:centerOfMass = (0, 0, 0)
        float physics:mass = 0.3
        quatd xformOp:orient = (0.7071067690849304, 0, 0, 0.7071067690849304)
        double3 xformOp:scale = (1, 1, 1)
        double3 xformOp:translate = (0.23499999940395355, 0.10000000149011612, 0.08249999582767487)
        uniform token[] xformOpOrder = ["xformOp:translate", "xformOp:orient", "xformOp:scale"]

        def Cylinder "visuals"
        {
            uniform token axis = "Z"
            float3[] extent = [(-0.0825, -0.0825, -0.0225), (0.0825, 0.0825, 0.0225)]
            double height = 0.04500000178813934
            rel material:binding = </wheelbot/Looks/material_PETG_orange>
            double radius = 0.08250000327825546
            quatd xformOp:orient = (0.4999999701976776, 0.4999999701976776, 0.4999999701976776, 0.4999999701976776)
            double3 xformOp:scale = (1, 1, 1)
            double3 xformOp:translate = (0, 0, 0)
            uniform token[] xformOpOrder = ["xformOp:translate", "xformOp:orient", "xformOp:scale"]
        }

        def Cylinder "collisions" (
            apiSchemas = ["PhysicsCollisionAPI"]
        )
        {
            uniform token axis = "Z"
            float3[] extent = [(-0.0825, -0.0825, -0.0225), (0.0825, 0.0825, 0.0225)]
            double height = 0.04500000178813934
            uniform token purpose = "guide"
            double radius = 0.08250000327825546
            quatd xformOp:orient = (0.7071067690849304, 0.7071067690849304, 0, 0)
            double3 xformOp:scale = (1, 1, 1)
            double3 xformOp:translate = (0, 0, 0)
            uniform token[] xformOpOrder = ["xformOp:translate", "xformOp:orient", "xformOp:scale"]
        }

        def PhysicsRevoluteJoint "FL_drive_right_joint" (
            apiSchemas = ["PhysxJointAPI", "PhysicsJointStateAPI:angular", "PhysicsDriveAPI:angular"]
        )
        {
            float drive:angular:physics:damping = 1000000
            float drive:angular:physics:maxForce = 100
            float drive:angular:physics:stiffness = 0
            float drive:angular:physics:targetVelocity = 0
            uniform token drive:angular:physics:type = "force"
            uniform token physics:axis = "X"
            rel physics:body0 = </wheelbot/FL_chassis_2_link>
            rel physics:body1 = </wheelbot/FL_wheel_drive_right>
            float physics:breakForce = 3.4028235e38
            float physics:breakTorque = 3.4028235e38
            point3f physics:localPos0 = (0, -0.115, 0)
            point3f physics:localPos1 = (0, 0, 0)
            quatf physics:localRot0 = (0.70710677, 0, 0, 0.70710677)
            quatf physics:localRot1 = (1, 0, 0, 0)
            float physxJoint:maxJointVelocity = 5729.578
        }
    }

    def Xform "FR_steering_link" (
        apiSchemas = ["PhysicsRigidBodyAPI", "PhysicsMassAPI"]
    )
    {
        float3 physics:diagonalInertia = (0.00001, 0.00001, 0.00001)
        float physics:mass = 0.000001
        quatd xformOp:orient = (1, 0, 0, 0)
        double3 xformOp:scale = (1, 1, 1)
        double3 xformOp:translate = (0.23499999940395355, -0.2150000035762787, 0.1809999942779541)
        uniform token[] xformOpOrder = ["xformOp:translate", "xformOp:orient", "xformOp:scale"]

        def Cylinder "visuals"
        {
            uniform token axis = "Z"
            float3[] extent = [(-0.064, -0.064, -0.016), (0.064, 0.064, 0.016)]
            double height = 0.03200000151991844
            rel material:binding = </wheelbot/Looks/material_Rubber>
            double radius = 0.06400000303983688
            quatd xformOp:orient = (1, 0, 0, 0)
            double3 xformOp:scale = (1, 1, 1)
            double3 xformOp:translate = (0, 0, 0)
            uniform token[] xformOpOrder = ["xformOp:translate", "xformOp:orient", "xformOp:scale"]
        }

        def PhysicsRevoluteJoint "FR_steering_joint" (
            apiSchemas = ["PhysxJointAPI", "PhysicsJointStateAPI:angular"]
        )
        {
            float drive:angular:physics:damping = 0.2
            float drive:angular:physics:maxForce = 100
            float drive:angular:physics:stiffness = 0
            uniform token drive:angular:physics:type = "force"
            uniform token physics:axis = "Z"
            rel physics:body0 = </wheelbot/chassis_link>
            rel physics:body1 = </wheelbot/FR_steering_link>
            float physics:breakForce = 3.4028235e38
            float physics:breakTorque = 3.4028235e38
            point3f physics:localPos0 = (0.235, -0.215, -0.036)
            point3f physics:localPos1 = (0, 0, 0)
            quatf physics:localRot0 = (1, 0, 0, 0)
            quatf physics:localRot1 = (1, 0, 0, 0)
            float physics:lowerLimit = -57.295776
            float physics:upperLimit = 57.295776
            float physxJoint:maxJointVelocity = 3.4028235e38
        }
    }

    def Xform "FR_chassis_2_link" (
        apiSchemas = ["PhysicsRigidBodyAPI", "PhysicsMassAPI"]
    )
    {
        point3f physics:centerOfMass = (0, 0, 0)
        float physics:mass = 5
        quatd xformOp:orient = (1, 0, 0, 0)
        double3 xformOp:scale = (1, 1, 1)
        double3 xformOp:translate = (0.23499999940395355, -0.2150000035762787, 0.08249999582767487)
        uniform token[] xformOpOrder = ["xformOp:translate", "xformOp:orient", "xformOp:scale"]

        def Cube "visuals"
        {
            float3[] extent = [(-0.045, -0.08, -0.045), (0.045, 0.08, 0.045)]
            rel material:binding = </wheelbot/Looks/material_Aluminium>
            double size = 1
            quatd xformOp:orient = (1, 0, 0, 0)
            double3 xformOp:scale = (0.09000000357627869, 0.1599999964237213, 0.09000000357627869)
            double3 xformOp:translate = (0, 0, 0)
            uniform token[] xformOpOrder = ["xformOp:translate", "xformOp:orient", "xformOp:scale"]
        }

        def Cube "collisions" (
            apiSchemas = ["PhysicsCollisionAPI"]
        )
        {
            float3[] extent = [(-0.045, -0.08, -0.045), (0.045, 0.08, 0.045)]
            uniform token purpose = "guide"
            double size = 1
            quatd xformOp:orient = (1, 0, 0, 0)
            double3 xformOp:scale = (0.09000000357627869, 0.1599999964237213, 0.09000000357627869)
            double3 xformOp:translate = (0, 0, 0)
            uniform token[] xformOpOrder = ["xformOp:translate", "xformOp:orient", "xformOp:scale"]
        }

        def PhysicsFixedJoint "FR_chassis_2_joint"
        {
            rel physics:body0 = </wheelbot/FR_steering_link>
            rel physics:body1 = </wheelbot/FR_chassis_2_link>
            float physics:breakForce = 3.4028235e38
            float physics:breakTorque = 3.4028235e38
            point3f physics:localPos0 = (0, 0, -0.0985)
            point3f physics:localPos1 = (0, 0, 0)
            quatf physics:localRot0 = (1, 0, 0, 0)
            quatf physics:localRot1 = (1, 0, 0, 0)
        }
    }

    def Xform "FR_wheel_drive_left" (
        apiSchemas = ["PhysicsRigidBodyAPI", "PhysicsMassAPI"]
    )
    {
        point3f physics:centerOfMass = (0, 0, 0)
        float physics:mass = 0.3
        quatd xformOp:orient = (0.7071067690849304, 0, 0, 0.7071067690849304)
        double3 xformOp:scale = (1, 1, 1)
        double3 xformOp:translate = (0.23499999940395355, -0.10000000149011612, 0.08249999582767487)
        uniform token[] xformOpOrder = ["xformOp:translate", "xformOp:orient", "xformOp:scale"]

        def Cylinder "visuals"
        {
            uniform token axis = "Z"
            float3[] extent = [(-0.0825, -0.0825, -0.0225), (0.0825, 0.0825, 0.0225)]
            double height = 0.04500000178813934
            rel material:binding = </wheelbot/Looks/material_PETG_orange>
            double radius = 0.08250000327825546
            quatd xformOp:orient = (0.4999999701976776, 0.4999999701976776, 0.4999999701976776, 0.4999999701976776)
            double3 xformOp:scale = (1, 1, 1)
            double3 xformOp:translate = (0, 0, 0)
            uniform token[] xformOpOrder = ["xformOp:translate", "xformOp:orient", "xformOp:scale"]
        }

        def Cylinder "collisions" (
            apiSchemas = ["PhysicsCollisionAPI"]
        )
        {
            uniform token axis = "Z"
            float3[] extent = [(-0.0825, -0.0825, -0.0225), (0.0825, 0.0825, 0.0225)]
            double height = 0.04500000178813934
            uniform token purpose = "guide"
            double radius = 0.08250000327825546
            quatd xformOp:orient = (0.7071067690849304, 0.7071067690849304, 0, 0)
            double3 xformOp:scale = (1, 1, 1)
            double3 xformOp:translate = (0, 0, 0)
            uniform token[] xformOpOrder = ["xformOp:translate", "xformOp:orient", "xformOp:scale"]
        }

        def PhysicsRevoluteJoint "FR_drive_left_joint" (
            apiSchemas = ["PhysxJointAPI", "PhysicsJointStateAPI:angular", "PhysicsDriveAPI:angular"]
        )
        {
            float drive:angular:physics:damping = 1000000
            float drive:angular:physics:maxForce = 100
            float drive:angular:physics:stiffness = 0
            float drive:angular:physics:targetVelocity = 0
            uniform token drive:angular:physics:type = "force"
            uniform token physics:axis = "X"
            rel physics:body0 = </wheelbot/FR_chassis_2_link>
            rel physics:body1 = </wheelbot/FR_wheel_drive_left>
            float physics:breakForce = 3.4028235e38
            float physics:breakTorque = 3.4028235e38
            point3f physics:localPos0 = (0, 0.115, 0)
            point3f physics:localPos1 = (0, 0, 0)
            quatf physics:localRot0 = (0.70710677, 0, 0, 0.70710677)
            quatf physics:localRot1 = (1, 0, 0, 0)
            float physxJoint:maxJointVelocity = 5729.578
        }
    }

    def Xform "FR_wheel_drive_right" (
        apiSchemas = ["PhysicsRigidBodyAPI", "PhysicsMassAPI"]
    )
    {
        point3f physics:centerOfMass = (0, 0, 0)
        float physics:mass = 0.3
        quatd xformOp:orient = (0.7071067690849304, 0, 0, 0.7071067690849304)
        double3 xformOp:scale = (1, 1, 1)
        double3 xformOp:translate = (0.23499999940395355, -0.33000001311302185, 0.08249999582767487)
        uniform token[] xformOpOrder = ["xformOp:translate", "xformOp:orient", "xformOp:scale"]

        def Cylinder "visuals"
        {
            uniform token axis = "Z"
            float3[] extent = [(-0.0825, -0.0825, -0.0225), (0.0825, 0.0825, 0.0225)]
            double height = 0.04500000178813934
            rel material:binding = </wheelbot/Looks/material_PETG_orange>
            double radius = 0.08250000327825546
            quatd xformOp:orient = (0.4999999701976776, 0.4999999701976776, 0.4999999701976776, 0.4999999701976776)
            double3 xformOp:scale = (1, 1, 1)
            double3 xformOp:translate = (0, 0, 0)
            uniform token[] xformOpOrder = ["xformOp:translate", "xformOp:orient", "xformOp:scale"]
        }

        def Cylinder "collisions" (
            apiSchemas = ["PhysicsCollisionAPI"]
        )
        {
            uniform token axis = "Z"
            float3[] extent = [(-0.0825, -0.0825, -0.0225), (0.0825, 0.0825, 0.0225)]
            double height = 0.04500000178813934
            uniform token purpose = "guide"
            double radius = 0.08250000327825546
            quatd xformOp:orient = (0.7071067690849304, 0.7071067690849304, 0, 0)
            double3 xformOp:scale = (1, 1, 1)
            double3 xformOp:translate = (0, 0, 0)
            uniform token[] xformOpOrder = ["xformOp:translate", "xformOp:orient", "xformOp:scale"]
        }

        def PhysicsRevoluteJoint "FR_drive_right_joint" (
            apiSchemas = ["PhysxJointAPI", "PhysicsJointStateAPI:angular", "PhysicsDriveAPI:angular"]
        )
        {
            float drive:angular:physics:damping = 1000000
            float drive:angular:physics:maxForce = 100
            float drive:angular:physics:stiffness = 0
            float drive:angular:physics:targetVelocity = 0
            uniform token drive:angular:physics:type = "force"
            uniform token physics:axis = "X"
            rel physics:body0 = </wheelbot/FR_chassis_2_link>
            rel physics:body1 = </wheelbot/FR_wheel_drive_right>
            float physics:breakForce = 3.4028235e38
            float physics:breakTorque = 3.4028235e38
            point3f physics:localPos0 = (0, -0.115, 0)
            point3f physics:localPos1 = (0, 0, 0)
            quatf physics:localRot0 = (0.70710677, 0, 0, 0.70710677)
            quatf physics:localRot1 = (1, 0, 0, 0)
            float physxJoint:maxJointVelocity = 5729.578
        }
    }

    def Xform "RL_steering_link" (
        apiSchemas = ["PhysicsRigidBodyAPI", "PhysicsMassAPI"]
    )
    {
        float3 physics:diagonalInertia = (0.00001, 0.00001, 0.00001)
        float physics:mass = 0.000001
        quatd xformOp:orient = (1, 0, 0, 0)
        double3 xformOp:scale = (1, 1, 1)
        double3 xformOp:translate = (-0.23499999940395355, 0.2150000035762787, 0.1809999942779541)
        uniform token[] xformOpOrder = ["xformOp:translate", "xformOp:orient", "xformOp:scale"]

        def Cylinder "visuals"
        {
            uniform token axis = "Z"
            float3[] extent = [(-0.064, -0.064, -0.016), (0.064, 0.064, 0.016)]
            double height = 0.03200000151991844
            rel material:binding = </wheelbot/Looks/material_Rubber>
            double radius = 0.06400000303983688
            quatd xformOp:orient = (1, 0, 0, 0)
            double3 xformOp:scale = (1, 1, 1)
            double3 xformOp:translate = (0, 0, 0)
            uniform token[] xformOpOrder = ["xformOp:translate", "xformOp:orient", "xformOp:scale"]
        }

        def PhysicsRevoluteJoint "RL_steering_joint" (
            apiSchemas = ["PhysxJointAPI", "PhysicsJointStateAPI:angular"]
        )
        {
            float drive:angular:physics:damping = 0.2
            float drive:angular:physics:maxForce = 100
            float drive:angular:physics:stiffness = 0
            uniform token drive:angular:physics:type = "force"
            uniform token physics:axis = "Z"
            rel physics:body0 = </wheelbot/chassis_link>
            rel physics:body1 = </wheelbot/RL_steering_link>
            float physics:breakForce = 3.4028235e38
            float physics:breakTorque = 3.4028235e38
            point3f physics:localPos0 = (-0.235, 0.215, -0.036)
            point3f physics:localPos1 = (0, 0, 0)
            quatf physics:localRot0 = (1, 0, 0, 0)
            quatf physics:localRot1 = (1, 0, 0, 0)
            float physics:lowerLimit = -57.295776
            float physics:upperLimit = 57.295776
            float physxJoint:maxJointVelocity = 3.4028235e38
        }
    }

    def Xform "RL_chassis_2_link" (
        apiSchemas = ["PhysicsRigidBodyAPI", "PhysicsMassAPI"]
    )
    {
        point3f physics:centerOfMass = (0, 0, 0)
        float physics:mass = 5
        quatd xformOp:orient = (1, 0, 0, 0)
        double3 xformOp:scale = (1, 1, 1)
        double3 xformOp:translate = (-0.23499999940395355, 0.2150000035762787, 0.08249999582767487)
        uniform token[] xformOpOrder = ["xformOp:translate", "xformOp:orient", "xformOp:scale"]

        def Cube "visuals"
        {
            float3[] extent = [(-0.045, -0.08, -0.045), (0.045, 0.08, 0.045)]
            rel material:binding = </wheelbot/Looks/material_Aluminium>
            double size = 1
            quatd xformOp:orient = (1, 0, 0, 0)
            double3 xformOp:scale = (0.09000000357627869, 0.1599999964237213, 0.09000000357627869)
            double3 xformOp:translate = (0, 0, 0)
            uniform token[] xformOpOrder = ["xformOp:translate", "xformOp:orient", "xformOp:scale"]
        }

        def Cube "collisions" (
            apiSchemas = ["PhysicsCollisionAPI"]
        )
        {
            float3[] extent = [(-0.045, -0.08, -0.045), (0.045, 0.08, 0.045)]
            uniform token purpose = "guide"
            double size = 1
            quatd xformOp:orient = (1, 0, 0, 0)
            double3 xformOp:scale = (0.09000000357627869, 0.1599999964237213, 0.09000000357627869)
            double3 xformOp:translate = (0, 0, 0)
            uniform token[] xformOpOrder = ["xformOp:translate", "xformOp:orient", "xformOp:scale"]
        }

        def PhysicsFixedJoint "RL_chassis_2_joint"
        {
            rel physics:body0 = </wheelbot/RL_steering_link>
            rel physics:body1 = </wheelbot/RL_chassis_2_link>
            float physics:breakForce = 3.4028235e38
            float physics:breakTorque = 3.4028235e38
            point3f physics:localPos0 = (0, 0, -0.0985)
            point3f physics:localPos1 = (0, 0, 0)
            quatf physics:localRot0 = (1, 0, 0, 0)
            quatf physics:localRot1 = (1, 0, 0, 0)
        }
    }

    def Xform "RL_wheel_drive_left" (
        apiSchemas = ["PhysicsRigidBodyAPI", "PhysicsMassAPI"]
    )
    {
        point3f physics:centerOfMass = (0, 0, 0)
        float physics:mass = 0.3
        quatd xformOp:orient = (0.7071067690849304, 0, 0, 0.7071067690849304)
        double3 xformOp:scale = (1, 1, 1)
        double3 xformOp:translate = (-0.23499999940395355, 0.33000001311302185, 0.08249999582767487)
        uniform token[] xformOpOrder = ["xformOp:translate", "xformOp:orient", "xformOp:scale"]

        def Cylinder "visuals"
        {
            uniform token axis = "Z"
            float3[] extent = [(-0.0825, -0.0825, -0.0225), (0.0825, 0.0825, 0.0225)]
            double height = 0.04500000178813934
            rel material:binding = </wheelbot/Looks/material_PETG_orange>
            double radius = 0.08250000327825546
            quatd xformOp:orient = (0.4999999701976776, 0.4999999701976776, 0.4999999701976776, 0.4999999701976776)
            double3 xformOp:scale = (1, 1, 1)
            double3 xformOp:translate = (0, 0, 0)
            uniform token[] xformOpOrder = ["xformOp:translate", "xformOp:orient", "xformOp:scale"]
        }

        def Cylinder "collisions" (
            apiSchemas = ["PhysicsCollisionAPI"]
        )
        {
            uniform token axis = "Z"
            float3[] extent = [(-0.0825, -0.0825, -0.0225), (0.0825, 0.0825, 0.0225)]
            double height = 0.04500000178813934
            uniform token purpose = "guide"
            double radius = 0.08250000327825546
            quatd xformOp:orient = (0.7071067690849304, 0.7071067690849304, 0, 0)
            double3 xformOp:scale = (1, 1, 1)
            double3 xformOp:translate = (0, 0, 0)
            uniform token[] xformOpOrder = ["xformOp:translate", "xformOp:orient", "xformOp:scale"]
        }

        def PhysicsRevoluteJoint "RL_drive_left_joint" (
            apiSchemas = ["PhysxJointAPI", "PhysicsJointStateAPI:angular", "PhysicsDriveAPI:angular"]
        )
        {
            float drive:angular:physics:damping = 1000000
            float drive:angular:physics:maxForce = 100
            float drive:angular:physics:stiffness = 0
            float drive:angular:physics:targetVelocity = 0
            uniform token drive:angular:physics:type = "force"
            uniform token physics:axis = "X"
            rel physics:body0 = </wheelbot/RL_chassis_2_link>
            rel physics:body1 = </wheelbot/RL_wheel_drive_left>
            float physics:breakForce = 3.4028235e38
            float physics:breakTorque = 3.4028235e38
            point3f physics:localPos0 = (0, 0.115, 0)
            point3f physics:localPos1 = (0, 0, 0)
            quatf physics:localRot0 = (0.70710677, 0, 0, 0.70710677)
            quatf physics:localRot1 = (1, 0, 0, 0)
            float physxJoint:maxJointVelocity = 5729.578
        }
    }

    def Xform "RL_wheel_drive_right" (
        apiSchemas = ["PhysicsRigidBodyAPI", "PhysicsMassAPI"]
    )
    {
        point3f physics:centerOfMass = (0, 0, 0)
        float physics:mass = 0.3
        quatd xformOp:orient = (0.7071067690849304, 0, 0, 0.7071067690849304)
        double3 xformOp:scale = (1, 1, 1)
        double3 xformOp:translate = (-0.23499999940395355, 0.10000000149011612, 0.08249999582767487)
        uniform token[] xformOpOrder = ["xformOp:translate", "xformOp:orient", "xformOp:scale"]

        def Cylinder "visuals"
        {
            uniform token axis = "Z"
            float3[] extent = [(-0.0825, -0.0825, -0.0225), (0.0825, 0.0825, 0.0225)]
            double height = 0.04500000178813934
            rel material:binding = </wheelbot/Looks/material_PETG_orange>
            double radius = 0.08250000327825546
            quatd xformOp:orient = (0.4999999701976776, 0.4999999701976776, 0.4999999701976776, 0.4999999701976776)
            double3 xformOp:scale = (1, 1, 1)
            double3 xformOp:translate = (0, 0, 0)
            uniform token[] xformOpOrder = ["xformOp:translate", "xformOp:orient", "xformOp:scale"]
        }

        def Cylinder "collisions" (
            apiSchemas = ["PhysicsCollisionAPI"]
        )
        {
            uniform token axis = "Z"
            float3[] extent = [(-0.0825, -0.0825, -0.0225), (0.0825, 0.0825, 0.0225)]
            double height = 0.04500000178813934
            uniform token purpose = "guide"
            double radius = 0.08250000327825546
            quatd xformOp:orient = (0.7071067690849304, 0.7071067690849304, 0, 0)
            double3 xformOp:scale = (1, 1, 1)
            double3 xformOp:translate = (0, 0, 0)
            uniform token[] xformOpOrder = ["xformOp:translate", "xformOp:orient", "xformOp:scale"]
        }

        def PhysicsRevoluteJoint "RL_drive_right_joint" (
            apiSchemas = ["PhysxJointAPI", "PhysicsJointStateAPI:angular", "PhysicsDriveAPI:angular"]
        )
        {
            float drive:angular:physics:damping = 1000000
            float drive:angular:physics:maxForce = 100
            float drive:angular:physics:stiffness = 0
            float drive:angular:physics:targetVelocity = 0
            uniform token drive:angular:physics:type = "force"
            uniform token physics:axis = "X"
            rel physics:body0 = </wheelbot/RL_chassis_2_link>
            rel physics:body1 = </wheelbot/RL_wheel_drive_right>
            float physics:breakForce = 3.4028235e38
            float physics:breakTorque = 3.4028235e38
            point3f physics:localPos0 = (0, -0.115, 0)
            point3f physics:localPos1 = (0, 0, 0)
            quatf physics:localRot0 = (0.70710677, 0, 0, 0.70710677)
            quatf physics:localRot1 = (1, 0, 0, 0)
            float physxJoint:maxJointVelocity = 5729.578
        }
    }

    def Xform "RR_steering_link" (
        apiSchemas = ["PhysicsRigidBodyAPI", "PhysicsMassAPI"]
    )
    {
        float3 physics:diagonalInertia = (0.00001, 0.00001, 0.00001)
        float physics:mass = 0.000001
        quatd xformOp:orient = (1, 0, 0, 0)
        double3 xformOp:scale = (1, 1, 1)
        double3 xformOp:translate = (-0.23499999940395355, -0.2150000035762787, 0.1809999942779541)
        uniform token[] xformOpOrder = ["xformOp:translate", "xformOp:orient", "xformOp:scale"]

        def Cylinder "visuals"
        {
            uniform token axis = "Z"
            float3[] extent = [(-0.064, -0.064, -0.016), (0.064, 0.064, 0.016)]
            double height = 0.03200000151991844
            rel material:binding = </wheelbot/Looks/material_Rubber>
            double radius = 0.06400000303983688
            quatd xformOp:orient = (1, 0, 0, 0)
            double3 xformOp:scale = (1, 1, 1)
            double3 xformOp:translate = (0, 0, 0)
            uniform token[] xformOpOrder = ["xformOp:translate", "xformOp:orient", "xformOp:scale"]
        }

        def PhysicsRevoluteJoint "RR_steering_joint" (
            apiSchemas = ["PhysxJointAPI", "PhysicsJointStateAPI:angular"]
        )
        {
            float drive:angular:physics:damping = 0.2
            float drive:angular:physics:maxForce = 100
            float drive:angular:physics:stiffness = 0
            uniform token drive:angular:physics:type = "force"
            uniform token physics:axis = "Z"
            rel physics:body0 = </wheelbot/chassis_link>
            rel physics:body1 = </wheelbot/RR_steering_link>
            float physics:breakForce = 3.4028235e38
            float physics:breakTorque = 3.4028235e38
            point3f physics:localPos0 = (-0.235, -0.215, -0.036)
            point3f physics:localPos1 = (0, 0, 0)
            quatf physics:localRot0 = (1, 0, 0, 0)
            quatf physics:localRot1 = (1, 0, 0, 0)
            float physics:lowerLimit = -57.295776
            float physics:upperLimit = 57.295776
            float physxJoint:maxJointVelocity = 3.4028235e38
        }
    }

    def Xform "RR_chassis_2_link" (
        apiSchemas = ["PhysicsRigidBodyAPI", "PhysicsMassAPI"]
    )
    {
        point3f physics:centerOfMass = (0, 0, 0)
        float physics:mass = 5
        quatd xformOp:orient = (1, 0, 0, 0)
        double3 xformOp:scale = (1, 1, 1)
        double3 xformOp:translate = (-0.23499999940395355, -0.2150000035762787, 0.08249999582767487)
        uniform token[] xformOpOrder = ["xformOp:translate", "xformOp:orient", "xformOp:scale"]

        def Cube "visuals"
        {
            float3[] extent = [(-0.045, -0.08, -0.045), (0.045, 0.08, 0.045)]
            rel material:binding = </wheelbot/Looks/material_Aluminium>
            double size = 1
            quatd xformOp:orient = (1, 0, 0, 0)
            double3 xformOp:scale = (0.09000000357627869, 0.1599999964237213, 0.09000000357627869)
            double3 xformOp:translate = (0, 0, 0)
            uniform token[] xformOpOrder = ["xformOp:translate", "xformOp:orient", "xformOp:scale"]
        }

        def Cube "collisions" (
            apiSchemas = ["PhysicsCollisionAPI"]
        )
        {
            float3[] extent = [(-0.045, -0.08, -0.045), (0.045, 0.08, 0.045)]
            uniform token purpose = "guide"
            double size = 1
            quatd xformOp:orient = (1, 0, 0, 0)
            double3 xformOp:scale = (0.09000000357627869, 0.1599999964237213, 0.09000000357627869)
            double3 xformOp:translate = (0, 0, 0)
            uniform token[] xformOpOrder = ["xformOp:translate", "xformOp:orient", "xformOp:scale"]
        }

        def PhysicsFixedJoint "RR_chassis_2_joint"
        {
            rel physics:body0 = </wheelbot/RR_steering_link>
            rel physics:body1 = </wheelbot/RR_chassis_2_link>
            float physics:breakForce = 3.4028235e38
            float physics:breakTorque = 3.4028235e38
            point3f physics:localPos0 = (0, 0, -0.0985)
            point3f physics:localPos1 = (0, 0, 0)
            quatf physics:localRot0 = (1, 0, 0, 0)
            quatf physics:localRot1 = (1, 0, 0, 0)
        }
    }

    def Xform "RR_wheel_drive_left" (
        apiSchemas = ["PhysicsRigidBodyAPI", "PhysicsMassAPI"]
    )
    {
        point3f physics:centerOfMass = (0, 0, 0)
        float physics:mass = 0.3
        quatd xformOp:orient = (0.7071067690849304, 0, 0, 0.7071067690849304)
        double3 xformOp:scale = (1, 1, 1)
        double3 xformOp:translate = (-0.23499999940395355, -0.10000000149011612, 0.08249999582767487)
        uniform token[] xformOpOrder = ["xformOp:translate", "xformOp:orient", "xformOp:scale"]

        def Cylinder "visuals"
        {
            uniform token axis = "Z"
            float3[] extent = [(-0.0825, -0.0825, -0.0225), (0.0825, 0.0825, 0.0225)]
            double height = 0.04500000178813934
            rel material:binding = </wheelbot/Looks/material_PETG_orange>
            double radius = 0.08250000327825546
            quatd xformOp:orient = (0.4999999701976776, 0.4999999701976776, 0.4999999701976776, 0.4999999701976776)
            double3 xformOp:scale = (1, 1, 1)
            double3 xformOp:translate = (0, 0, 0)
            uniform token[] xformOpOrder = ["xformOp:translate", "xformOp:orient", "xformOp:scale"]
        }

        def Cylinder "collisions" (
            apiSchemas = ["PhysicsCollisionAPI"]
        )
        {
            uniform token axis = "Z"
            float3[] extent = [(-0.0825, -0.0825, -0.0225), (0.0825, 0.0825, 0.0225)]
            double height = 0.04500000178813934
            uniform token purpose = "guide"
            double radius = 0.08250000327825546
            quatd xformOp:orient = (0.7071067690849304, 0.7071067690849304, 0, 0)
            double3 xformOp:scale = (1, 1, 1)
            double3 xformOp:translate = (0, 0, 0)
            uniform token[] xformOpOrder = ["xformOp:translate", "xformOp:orient", "xformOp:scale"]
        }

        def PhysicsRevoluteJoint "RR_drive_left_joint" (
            apiSchemas = ["PhysxJointAPI", "PhysicsJointStateAPI:angular", "PhysicsDriveAPI:angular"]
        )
        {
            float drive:angular:physics:damping = 1000000
            float drive:angular:physics:maxForce = 100
            float drive:angular:physics:stiffness = 0
            float drive:angular:physics:targetVelocity = 0
            uniform token drive:angular:physics:type = "force"
            uniform token physics:axis = "X"
            rel physics:body0 = </wheelbot/RR_chassis_2_link>
            rel physics:body1 = </wheelbot/RR_wheel_drive_left>
            float physics:breakForce = 3.4028235e38
            float physics:breakTorque = 3.4028235e38
            point3f physics:localPos0 = (0, 0.115, 0)
            point3f physics:localPos1 = (0, 0, 0)
            quatf physics:localRot0 = (0.70710677, 0, 0, 0.70710677)
            quatf physics:localRot1 = (1, 0, 0, 0)
            float physxJoint:maxJointVelocity = 5729.578
        }
    }

    def Xform "RR_wheel_drive_right" (
        apiSchemas = ["PhysicsRigidBodyAPI", "PhysicsMassAPI"]
    )
    {
        point3f physics:centerOfMass = (0, 0, 0)
        float physics:mass = 0.3
        quatd xformOp:orient = (0.7071067690849304, 0, 0, 0.7071067690849304)
        double3 xformOp:scale = (1, 1, 1)
        double3 xformOp:translate = (-0.23499999940395355, -0.33000001311302185, 0.08249999582767487)
        uniform token[] xformOpOrder = ["xformOp:translate", "xformOp:orient", "xformOp:scale"]

        def Cylinder "visuals"
        {
            uniform token axis = "Z"
            float3[] extent = [(-0.0825, -0.0825, -0.0225), (0.0825, 0.0825, 0.0225)]
            double height = 0.04500000178813934
            rel material:binding = </wheelbot/Looks/material_PETG_orange>
            double radius = 0.08250000327825546
            quatd xformOp:orient = (0.4999999701976776, 0.4999999701976776, 0.4999999701976776, 0.4999999701976776)
            double3 xformOp:scale = (1, 1, 1)
            double3 xformOp:translate = (0, 0, 0)
            uniform token[] xformOpOrder = ["xformOp:translate", "xformOp:orient", "xformOp:scale"]
        }

        def Cylinder "collisions" (
            apiSchemas = ["PhysicsCollisionAPI"]
        )
        {
            uniform token axis = "Z"
            float3[] extent = [(-0.0825, -0.0825, -0.0225), (0.0825, 0.0825, 0.0225)]
            double height = 0.04500000178813934
            uniform token purpose = "guide"
            double radius = 0.08250000327825546
            quatd xformOp:orient = (0.7071067690849304, 0.7071067690849304, 0, 0)
            double3 xformOp:scale = (1, 1, 1)
            double3 xformOp:translate = (0, 0, 0)
            uniform token[] xformOpOrder = ["xformOp:translate", "xformOp:orient", "xformOp:scale"]
        }

        def PhysicsRevoluteJoint "RR_drive_right_joint" (
            apiSchemas = ["PhysxJointAPI", "PhysicsJointStateAPI:angular", "PhysicsDriveAPI:angular"]
        )
        {
            float drive:angular:physics:damping = 1000000
            float drive:angular:physics:maxForce = 100
            float drive:angular:physics:stiffness = 0
            float drive:angular:physics:targetVelocity = 0
            uniform token drive:angular:physics:type = "force"
            uniform token physics:axis = "X"
            rel physics:body0 = </wheelbot/RR_chassis_2_link>
            rel physics:body1 = </wheelbot/RR_wheel_drive_right>
            float physics:breakForce = 3.4028235e38
            float physics:breakTorque = 3.4028235e38
            point3f physics:localPos0 = (0, -0.115, 0)
            point3f physics:localPos1 = (0, 0, 0)
            quatf physics:localRot0 = (0.70710677, 0, 0, 0.70710677)
            quatf physics:localRot1 = (1, 0, 0, 0)
            float physxJoint:maxJointVelocity = 5729.578
        }
    }
}

